Traceback (most recent call last):
  File "/Users/hjensen/opt/anaconda3/lib/python3.8/site-packages/jupyter_cache/executors/utils.py", line 51, in single_nb_execution
    executenb(
  File "/Users/hjensen/opt/anaconda3/lib/python3.8/site-packages/nbclient/client.py", line 1082, in execute
    return NotebookClient(nb=nb, resources=resources, km=km, **kwargs).execute()
  File "/Users/hjensen/opt/anaconda3/lib/python3.8/site-packages/nbclient/util.py", line 74, in wrapped
    return just_run(coro(*args, **kwargs))
  File "/Users/hjensen/opt/anaconda3/lib/python3.8/site-packages/nbclient/util.py", line 53, in just_run
    return loop.run_until_complete(coro)
  File "/Users/hjensen/opt/anaconda3/lib/python3.8/asyncio/base_events.py", line 616, in run_until_complete
    return future.result()
  File "/Users/hjensen/opt/anaconda3/lib/python3.8/site-packages/nbclient/client.py", line 535, in async_execute
    await self.async_execute_cell(
  File "/Users/hjensen/opt/anaconda3/lib/python3.8/site-packages/nbclient/client.py", line 827, in async_execute_cell
    self._check_raise_for_error(cell, exec_reply)
  File "/Users/hjensen/opt/anaconda3/lib/python3.8/site-packages/nbclient/client.py", line 735, in _check_raise_for_error
    raise CellExecutionError.from_cell_and_msg(cell, exec_reply['content'])
nbclient.exceptions.CellExecutionError: An error occurred while executing the following cell:
------------------
# Common imports
import numpy as np
import pandas as pd
import matplotlib.pyplot as plt
import sklearn.linear_model as skl
from sklearn.model_selection import train_test_split
from sklearn.metrics import mean_squared_error, r2_score, mean_absolute_error
import os

# Where to save the figures and data files
PROJECT_ROOT_DIR = "Results"
FIGURE_ID = "Results/FigureFiles"
DATA_ID = "DataFiles/"

if not os.path.exists(PROJECT_ROOT_DIR):
    os.mkdir(PROJECT_ROOT_DIR)

if not os.path.exists(FIGURE_ID):
    os.makedirs(FIGURE_ID)

if not os.path.exists(DATA_ID):
    os.makedirs(DATA_ID)

def image_path(fig_id):
    return os.path.join(FIGURE_ID, fig_id)

def data_path(dat_id):
    return os.path.join(DATA_ID, dat_id)

def save_fig(fig_id):
    plt.savefig(image_path(fig_id) + ".png", format='png')

infile = open(data_path("MassEval2016.dat"),'r')
------------------

[0;31m---------------------------------------------------------------------------[0m
[0;31mFileNotFoundError[0m                         Traceback (most recent call last)
[0;32m<ipython-input-28-3cd19a0768e1>[0m in [0;36m<module>[0;34m[0m
[1;32m     31[0m     [0mplt[0m[0;34m.[0m[0msavefig[0m[0;34m([0m[0mimage_path[0m[0;34m([0m[0mfig_id[0m[0;34m)[0m [0;34m+[0m [0;34m".png"[0m[0;34m,[0m [0mformat[0m[0;34m=[0m[0;34m'png'[0m[0;34m)[0m[0;34m[0m[0;34m[0m[0m
[1;32m     32[0m [0;34m[0m[0m
[0;32m---> 33[0;31m [0minfile[0m [0;34m=[0m [0mopen[0m[0;34m([0m[0mdata_path[0m[0;34m([0m[0;34m"MassEval2016.dat"[0m[0;34m)[0m[0;34m,[0m[0;34m'r'[0m[0;34m)[0m[0;34m[0m[0;34m[0m[0m
[0m
[0;31mFileNotFoundError[0m: [Errno 2] No such file or directory: 'DataFiles/MassEval2016.dat'
FileNotFoundError: [Errno 2] No such file or directory: 'DataFiles/MassEval2016.dat'

